<?xml version="1.0" encoding="utf-8"?>
<robot name="ur5e">
  <material name="silver">
		<color rgba="0.73 0.7764 0.7882 1"/>
	</material>
  <material name="white">
    <color rgba="1 1 1 1"/>
  </material>
  <link name="base_link">
    <visual>
      <geometry>
        <mesh filename="meshes/ur5e/visual/base.dae"/>
      </geometry>
      <origin rpy="1.57079632679 0 0" xyz="0.0 0.0 0.0"/>
      <!-- <material name="LightGrey">
        <color rgba="0.7 0.7 0.7 1.0"/>
      </material> -->
    </visual>
    <collision>
      <geometry>
        <mesh filename="meshes/ur5e/collision/base.stl" scale="1.0 1.0 1.0"/>
      </geometry>
    </collision>
    <inertial>
      <mass value="4.0"/>
      <origin rpy="0 0 0" xyz="0.0 0.0 0.0"/>
      <inertia ixx="0.00443333156" ixy="0.0" ixz="0.0" iyy="0.00443333156" iyz="0.0" izz="0.0072"/>
    </inertial>
  </link>
  <joint name="shoulder_pan_joint" type="revolute">
    <parent link="base_link"/>
    <child link="shoulder_link"/>
    <origin rpy="0.0 0.0 0.0" xyz="0.0 0.0 0.163"/>
    <axis xyz="0 0 1"/>
    <limit effort="150.0" lower="-6.28318530718" upper="6.28318530718" velocity="3.14"/>
    <dynamics damping="0.0" friction="0.0"/>
  </joint>
  <link name="shoulder_link">
    <visual>
      <geometry>
        <mesh filename="meshes/ur5e/visual/shoulder.dae"/>
      </geometry>
      <origin rpy="1.57079632679 0 0" xyz="0.0 0.0 0.0"/>
      <!-- <material name="LightGrey">
        <color rgba="0.7 0.7 0.7 1.0"/>
      </material> -->
    </visual>
    <collision>
      <geometry>
        <mesh filename="meshes/ur5e/collision/shoulder.stl" scale="1.0 1.0 1.0"/>
      </geometry>
    </collision>
    <inertial>
      <mass value="3.7"/>
      <origin rpy="0 0 0" xyz="0.0 0.0 0.0"/>
      <inertia ixx="0.010267495893" ixy="0.0" ixz="0.0" iyy="0.010267495893" iyz="0.0" izz="0.00666"/>
    </inertial>
  </link>
  <joint name="shoulder_lift_joint" type="revolute">
    <parent link="shoulder_link"/>
    <child link="upper_arm_link"/>
    <origin rpy="0.0 1.57079632679 0.0" xyz="0.0 0.138 0.0"/>
    <axis xyz="0 1 0"/>
    <limit effort="150.0" lower="-6.28318530718" upper="6.28318530718" velocity="3.14"/>
    <dynamics damping="0.0" friction="0.0"/>
  </joint>
  <link name="upper_arm_link">
    <visual>
      <geometry>
        <mesh filename="meshes/ur5e/visual/upperarm.dae"/>
      </geometry>
      <origin rpy="1.57079632679 0 0" xyz="0.0 0.0 0.0"/>
      <!-- <material name="LightGrey">
        <color rgba="0.7 0.7 0.7 1.0"/>
      </material> -->
    </visual>
    <collision>
      <geometry>
        <mesh filename="meshes/ur5e/collision/upperarm.stl" scale="1.0 1.0 1.0"/>
      </geometry>
    </collision>
    <inertial>
      <mass value="8.393"/>
      <origin rpy="0 0 0" xyz="0.0 0.0 0.2125"/>
      <inertia ixx="0.133885781862" ixy="0.0" ixz="0.0" iyy="0.133885781862" iyz="0.0" izz="0.0151074"/>
    </inertial>
  </link>
  <joint name="elbow_joint" type="revolute">
    <parent link="upper_arm_link"/>
    <child link="forearm_link"/>
    <origin rpy="0.0 0.0 0.0" xyz="0.0 -0.131 0.425"/>
    <axis xyz="0 1 0"/>
    <limit effort="150.0" lower="-3.14159265359" upper="3.14159265359" velocity="3.14"/>
    <dynamics damping="0.0" friction="0.0"/>
  </joint>
  <link name="forearm_link">
    <visual>
      <geometry>
        <mesh filename="meshes/ur5e/visual/forearm.dae"/>
      </geometry>
      <origin rpy="1.57079632679 0 0" xyz="0.0 0.0 0.0"/>
      <!-- <material name="LightGrey">
        <color rgba="0.7 0.7 0.7 1.0"/>
      </material> -->
    </visual>
    <collision>
      <geometry>
        <mesh filename="meshes/ur5e/collision/forearm.stl" scale="1.0 1.0 1.0"/>
      </geometry>
    </collision>
    <inertial>
      <mass value="2.275"/>
      <origin rpy="0 0 0" xyz="0.0 0.0 0.196"/>
      <inertia ixx="0.0311796208615" ixy="0.0" ixz="0.0" iyy="0.0311796208615" iyz="0.0" izz="0.004095"/>
    </inertial>
  </link>
  <joint name="wrist_1_joint" type="revolute">
    <parent link="forearm_link"/>
    <child link="wrist_1_link"/>
    <origin rpy="0.0 1.57079632679 0.0" xyz="0.0 0.0 0.392"/>
    <axis xyz="0 1 0"/>
    <limit effort="28.0" lower="-6.28318530718" upper="6.28318530718" velocity="6.28"/>
    <dynamics damping="0.0" friction="0.0"/>
  </joint>
  <link name="wrist_1_link">
    <visual>
      <geometry>
        <mesh filename="meshes/ur5e/visual/wrist1.dae"/>
      </geometry>
      <origin rpy="1.57079632679 0 0" xyz="0.0 0.0 0.0"/>
      <!-- <material name="LightGrey">
        <color rgba="0.7 0.7 0.7 1.0"/>
      </material> -->
    </visual>
    <collision>
      <geometry>
        <mesh filename="meshes/ur5e/collision/wrist1.stl" scale="1.0 1.0 1.0"/>
      </geometry>
    </collision>
    <inertial>
      <mass value="1.219"/>
      <origin rpy="0 0 0" xyz="0.0 0.127 0.0"/>
      <inertia ixx="0.00255989897604" ixy="0.0" ixz="0.0" iyy="0.00255989897604" iyz="0.0" izz="0.0021942"/>
    </inertial>
  </link>
  <joint name="wrist_2_joint" type="revolute">
    <parent link="wrist_1_link"/>
    <child link="wrist_2_link"/>
    <origin rpy="0.0 0.0 0.0" xyz="0.0 0.127 0.0"/>
    <axis xyz="0 0 1"/>
    <limit effort="28.0" lower="-6.28318530718" upper="6.28318530718" velocity="6.28"/>
    <dynamics damping="0.0" friction="0.0"/>
  </joint>
  <link name="wrist_2_link">
    <visual>
      <geometry>
        <mesh filename="meshes/ur5e/visual/wrist2.dae"/>
      </geometry>
      <origin rpy="1.57079632679 0 0" xyz="0.0 0.0 0.0"/>
      <!-- <material name="LightGrey">
        <color rgba="0.7 0.7 0.7 1.0"/>
      </material> -->
    </visual>
    <collision>
      <geometry>
        <mesh filename="meshes/ur5e/collision/wrist2.stl" scale="1.0 1.0 1.0"/>
      </geometry>
    </collision>
    <inertial>
      <mass value="1.219"/>
      <origin rpy="0 0 0" xyz="0.0 0.0 0.1"/>
      <inertia ixx="0.00255989897604" ixy="0.0" ixz="0.0" iyy="0.00255989897604" iyz="0.0" izz="0.0021942"/>
    </inertial>
  </link>
  <joint name="wrist_3_joint" type="revolute">
    <parent link="wrist_2_link"/>
    <child link="wrist_3_link"/>
    <origin rpy="0.0 0.0 0.0" xyz="0.0 0.0 0.1"/>
    <axis xyz="0 1 0"/>
    <limit effort="28.0" lower="-6.28318530718" upper="6.28318530718" velocity="6.28"/>
    <dynamics damping="0.0" friction="0.0"/>
  </joint>
  <link name="wrist_3_link">
    <visual>
      <geometry>
        <mesh filename="meshes/ur5e/visual/wrist3.dae"/>
      </geometry>
      <origin rpy="1.57079632679 0 0" xyz="0.0 0.0 0.0"/>
      <!-- <material name="LightGrey">
        <color rgba="0.7 0.7 0.7 1.0"/>
      </material> -->
    </visual>
    <collision>
      <geometry>
        <mesh filename="meshes/ur5e/collision/wrist3.stl" scale="1.0 1.0 1.0"/>
      </geometry>
    </collision>
    <inertial>
      <mass value="0.1879"/>
      <origin rpy="1.57079632679 0 0" xyz="0.0 0.0771 0.0"/>
      <inertia ixx="9.89041005217e-05" ixy="0.0" ixz="0.0" iyy="9.89041005217e-05" iyz="0.0" izz="0.0001321171875"/>
    </inertial>
  </link>
  <joint name="ee_fixed_joint" type="fixed">
    <parent link="wrist_3_link"/>
    <child link="ee_link"/>
    <origin rpy="0.0 0.0 1.57079632679" xyz="0.0 0.1 0.0"/>
  </joint>
  <link name="ee_link">
    <collision>
      <geometry>
        <box size="0.01 0.01 0.01"/>
      </geometry>
      <origin rpy="0 0 0" xyz="-0.01 0 0"/>
    </collision>
  </link>

<link name="ee_link">
    <collision>
      <geometry>
        <box size="0.01 0.01 0.01"/>
      </geometry>
      <origin rpy="0 0 0" xyz="-0.01 0 0"/>
    </collision>
  </link>

  <link name="gripper_center">
  </link>
  <joint name="gripper_center_joint" type="fixed">
    <parent link="ee_link"/>
    <child link="gripper_center"/>
    <origin rpy="0.00000 0.00000 0.00000" xyz="0.1901 0.0 0.0"/>
  </joint>
  <!-- ====================Attach AllegroHand (right)==================== -->


  <!-- Hand Links -->
  <joint name="hand_joint" type="fixed">
    	<parent link="ee_link"/>
    	<child link="hand_link"/>
    	<origin rpy="0 0 0" xyz="0.001 0 0"/>
    </joint>
    <link name="hand_link">
    	<collision>
      	<origin rpy="0.00 0.00 0.00" xyz="0.00 0.00 0.00"/>
      	<geometry>
        	<mesh filename="meshes/rg2_gripper/meshes/collision/RG2_Hand_col.STL"/>
      	</geometry>
    	</collision>
    	<visual>
      	<origin rpy="0.00 0.00 0.00" xyz="0.00 0.00 0.00"/>
      	<geometry>
        	<mesh filename="meshes/rg2_gripper/meshes/visual/RG2_Hand_vis.STL"/>
      	</geometry>
	<material name="silver"/>
    	</visual>
    	<inertial>
      		<origin rpy="0.00 0.00 0.00" xyz="0.061902 0.000129 -0.000005"/>
      		<mass value="1.684558"/>
      		<inertia ixx="0.000862" ixy="0.000000" ixz="0.000000" iyy="0.002401" iyz="-0.000001" izz="0.002620"/>
    	</inertial>
    </link>
    <joint name="gripper_joint" type="revolute">
    	<parent link="hand_link"/>
    	<child link="l_moment_arm_link"/>
    	<origin rpy="0 0 0" xyz="0.105 0.017 0.010"/>
    	<axis xyz="0 0 1"/>
    	<limit effort="10.6" lower="-1.570796327" upper="1.570796327" velocity="3.14"/>
	<dynamics damping="0.1" friction="0.0" />
        <implicitSpringDamper>True</implicitSpringDamper>
    </joint>
    <link name="l_moment_arm_link">
    	<collision>
        	<origin rpy="0.00 0.00 0.00" xyz="0.00 0.00 0.00"/>
        	<geometry>
         		<mesh filename="meshes/rg2_gripper/meshes/collision/RG2_LeftMomentArm_col.STL"/>
      		</geometry>
    	</collision>
     	<visual>
        	<origin rpy="0.00 0.00 0.00" xyz="0.00 0.00 0.00"/>
        	<geometry>
          		<mesh filename="meshes/rg2_gripper/meshes/visual/RG2_LeftMomentArm_vis.STL"/>
        	</geometry>
		<material name="silver"/>
      	</visual>
      	<inertial>
        	<origin rpy="0.00 0.00 0.00" xyz="0.017004 0.006397 -0.010300"/>
        	<mass value="0.160209"/>
        	<inertia ixx="0.000023" ixy="0.000019" ixz="0.000000" iyy="0.000072" iyz="0.000000" izz="0.000083"/>
      		</inertial>
    </link>
    <joint name="l_finger_2_joint" type="revolute">
    	<parent link="l_moment_arm_link"/>
    	<child link="l_finger_link"/>
    	<origin rpy="0 0 0" xyz="0.049 0.026 0.0"/>
    	<axis xyz="0 0 1"/>
    	<limit effort="10.6" lower="-3.14159" upper="3.14159" velocity="3.14"/>
	<mimic joint="gripper_joint" multiplier="-1"/>
        <dynamics damping="0.1" friction="0.0" />
        <implicitSpringDamper>True</implicitSpringDamper>
    </joint>
    <link name="l_finger_link">
    	<collision>
      		<origin rpy="0.00 0.00 0.00" xyz="0.00 0.00 0.00"/>
      		<geometry>
        		<mesh filename="meshes/rg2_gripper/meshes/visual/RG2_LeftFinger_vis.STL"/>
      		</geometry>
    	</collision>
    	<visual>
      		<origin rpy="0.00 0.00 0.00" xyz="0.00 0.00 0.00"/>
      		<geometry>
        		<mesh filename="meshes/rg2_gripper/meshes/visual/RG2_LeftFinger_vis.STL"/>
      		</geometry>
		<material name="black"/>
    	</visual>
    	<inertial>
      		<origin rpy="0.00 0.00 0.00" xyz="0.024695 -0.010178 -0.010001"/>
      		<mass value="0.081638"/>
      		<inertia ixx="0.000006" ixy="-0.000005" ixz="0.000000" iyy="0.000025" iyz="0.000000" izz="0.000026"/>
    	</inertial>
    </link>
    <joint name="r_finger_1_joint" type="revolute">
    	<parent link="hand_link"/>
    	<child link="r_moment_arm_link"/>
    	<origin rpy="0 0 0" xyz="0.105 -0.017 0.010"/>
    	<axis xyz="0 0 1"/>
    	<limit effort="10.6" lower="-1.570796327" upper="1.570796327" velocity="3.14"/>
 	<mimic joint="gripper_joint" multiplier="-1"/>
        <dynamics damping="0.1" friction="0.0" />
	<implicitSpringDamper>True</implicitSpringDamper>
    </joint>
    <link name="r_moment_arm_link">
    	<collision>
      		<origin rpy="0.00 0.00 0.00" xyz="0.00 0.00 0.00"/>
      		<geometry>
        		<mesh filename="meshes/rg2_gripper/meshes/collision/RG2_RightMomentArm_col.STL"/>
      		</geometry>
    	</collision>
    	<visual>
      		<origin rpy="0.00 0.00 0.00" xyz="0.00 0.00 0.00"/>
      		<geometry>
        		<mesh filename="meshes/rg2_gripper/meshes/visual/RG2_RightMomentArm_vis.STL"/>
      		</geometry>
		<material name="silver"/>
    	</visual>
    	<inertial>
      		<origin rpy="0.00 0.00 0.00" xyz="0.017004 -0.006397 -0.010300"/>
      		<mass value="0.160209"/>
      		<inertia ixx="0.000023" ixy="-0.000019" ixz="0.000000" iyy="0.000072" iyz="0.000000" izz="0.000083"/>
    	</inertial>
    </link>
    <joint name="r_finger_2_joint" type="revolute">
    	<parent link="r_moment_arm_link"/>
    	<child link="r_finger_link"/>
    	<origin rpy="0 0 0" xyz="0.049 -0.026 0.0"/>
    	<axis xyz="0 0 1"/>
    	<limit effort="10.6" lower="-3.14159" upper="3.14159" velocity="3.14"/>
	<mimic joint="gripper_joint" multiplier="1"/>
        <dynamics damping="0.1" friction="0.0" />
        <implicitSpringDamper>True</implicitSpringDamper>
    </joint>
    <link name="r_finger_link">
    	<collision>
      		<origin rpy="0.00 0.00 0.00" xyz="0.00 0.00 0.00"/>
      		<geometry>
        		<mesh filename="meshes/rg2_gripper/meshes/visual/RG2_RightFinger_vis.STL"/>
      		</geometry>
    	</collision>
    	<visual>
      		<origin rpy="0.00 0.00 0.00" xyz="0.00 0.00 0.00"/>
      		<geometry>
        		<mesh filename="meshes/rg2_gripper/meshes/visual/RG2_RightFinger_vis.STL"/>
      		</geometry>
		<material name="black"/>
    	</visual>
    	<inertial>
      		<origin rpy="0.00 0.00 0.00" xyz="0.024695 0.010178 -0.010000"/>
      		<mass value="0.081637"/>
      		<inertia ixx="0.000006" ixy="0.000005" ixz="0.000000" iyy="0.000025" iyz="0.000000" izz="0.000026"/>
    	</inertial>
    </link>
    <!-- Left finger joint and link -->
    <joint name="ur10_leftfinger_tip_joint" type="fixed">
        <parent link="l_finger_link"/>
        <child link="ur10_leftfinger_tip"/>
        <origin rpy="0 0 0" xyz="0.035 -0.01 -0.015"/>
    </joint>
    <link name="ur10_leftfinger_tip">
        <collision>
            <geometry>
                <box size="0.013 0.004 0.001"/> <!-- 0.0을 0.001로 수정 -->
            </geometry>
        </collision>
    </link>

    <!-- Right finger joint and link -->
    <joint name="ur10_rightfinger_tip_joint" type="fixed">
        <parent link="r_finger_link"/>
        <child link="ur10_rightfinger_tip"/>
        <origin rpy="0 0 0" xyz="0.035 0.01 -0.015"/>
    </joint>
    <link name="ur10_rightfinger_tip">
        <collision>
            <geometry>
                <box size="0.013 0.004 0.001"/> <!-- 0.0을 0.001로 수정 -->
            </geometry>
        </collision>
    </link>
    <joint name="ur10_leftfinger_ft_sensor_joint" type="fixed">
        <parent link="r_finger_link"/>
        <child link="ur10_leftfinger_ft_sensor"/>
        <origin rpy="1.57 1.57 0" xyz="0.035 0.02 -0.01"/>
    </joint>
    <link name="ur10_leftfinger_ft_sensor">
        <visual>
            <origin rpy="0 0 0" xyz="0 0 0"/>
            <geometry>
                <cylinder radius="0.015" length="0.001"/>
            </geometry>
            <material name="red">
                <color rgba="1.0 0.0 0.0 1.0"/>
            </material>
        </visual>
        <collision>
            <origin rpy="0 0 0" xyz="0 0 0"/>
            <geometry>
                <cylinder radius="0.015" length="0.001"/>
            </geometry>
        </collision>
    </link>
    <joint name="ur10_rightfinger_ft_sensor_joint" type="fixed">
        <parent link="l_finger_link"/>
        <child link="ur10_rightfinger_ft_sensor"/>
        <origin rpy="1.57 1.57 0" xyz="0.035 -0.02 -0.01"/>
    </joint>
    <link name="ur10_rightfinger_ft_sensor">
        <visual>
            <origin rpy="0 0 1.57" xyz="0 0 0"/>
            <geometry>
                <cylinder radius="0.015" length="0.001"/>
            </geometry>
            <material name="red">
                <color rgba="1.0 0.0 0.0 1.0"/>
            </material>
        </visual>
        <collision>
            <origin rpy="0 0 1.57" xyz="0 0 0"/>
            <geometry>
                <cylinder radius="0.015" length="0.001"/>
            </geometry>
        </collision>
    </link>
</robot>


