<?xml version="1.0" encoding="utf-8"?>
<robot name="ur5e">
  <material name="silver">
		<color rgba="0.73 0.7764 0.7882 1"/>
	</material>
  <material name="white">
    <color rgba="1 1 1 1"/>
  </material>
  <link name="base_link">
    <visual>
      <geometry>
        <mesh filename="meshes/ur5e/visual/base.dae"/>
      </geometry>
      <origin rpy="1.57079632679 0 0" xyz="0.0 0.0 0.0"/>
      <!-- <material name="LightGrey">
        <color rgba="0.7 0.7 0.7 1.0"/>
      </material> -->
    </visual>
    <collision>
      <geometry>
        <mesh filename="meshes/ur5e/collision/base.stl" scale="1.0 1.0 1.0"/>
      </geometry>
    </collision>
    <inertial>
      <mass value="4.0"/>
      <origin rpy="0 0 0" xyz="0.0 0.0 0.0"/>
      <inertia ixx="0.00443333156" ixy="0.0" ixz="0.0" iyy="0.00443333156" iyz="0.0" izz="0.0072"/>
    </inertial>
  </link>
  <joint name="shoulder_pan_joint" type="revolute">
    <parent link="base_link"/>
    <child link="shoulder_link"/>
    <origin rpy="0.0 0.0 0.0" xyz="0.0 0.0 0.163"/>
    <axis xyz="0 0 1"/>
    <limit effort="150.0" lower="-6.28318530718" upper="6.28318530718" velocity="3.14"/>
    <dynamics damping="0.0" friction="0.0"/>
  </joint>
  <link name="shoulder_link">
    <visual>
      <geometry>
        <mesh filename="meshes/ur5e/visual/shoulder.dae"/>
      </geometry>
      <origin rpy="1.57079632679 0 0" xyz="0.0 0.0 0.0"/>
      <!-- <material name="LightGrey">
        <color rgba="0.7 0.7 0.7 1.0"/>
      </material> -->
    </visual>
    <collision>
      <geometry>
        <mesh filename="meshes/ur5e/collision/shoulder.stl" scale="1.0 1.0 1.0"/>
      </geometry>
    </collision>
    <inertial>
      <mass value="3.7"/>
      <origin rpy="0 0 0" xyz="0.0 0.0 0.0"/>
      <inertia ixx="0.010267495893" ixy="0.0" ixz="0.0" iyy="0.010267495893" iyz="0.0" izz="0.00666"/>
    </inertial>
  </link>
  <joint name="shoulder_lift_joint" type="revolute">
    <parent link="shoulder_link"/>
    <child link="upper_arm_link"/>
    <origin rpy="0.0 1.57079632679 0.0" xyz="0.0 0.138 0.0"/>
    <axis xyz="0 1 0"/>
    <limit effort="150.0" lower="-6.28318530718" upper="6.28318530718" velocity="3.14"/>
    <dynamics damping="0.0" friction="0.0"/>
  </joint>
  <link name="upper_arm_link">
    <visual>
      <geometry>
        <mesh filename="meshes/ur5e/visual/upperarm.dae"/>
      </geometry>
      <origin rpy="1.57079632679 0 0" xyz="0.0 0.0 0.0"/>
      <!-- <material name="LightGrey">
        <color rgba="0.7 0.7 0.7 1.0"/>
      </material> -->
    </visual>
    <collision>
      <geometry>
        <mesh filename="meshes/ur5e/collision/upperarm.stl" scale="1.0 1.0 1.0"/>
      </geometry>
    </collision>
    <inertial>
      <mass value="8.393"/>
      <origin rpy="0 0 0" xyz="0.0 0.0 0.2125"/>
      <inertia ixx="0.133885781862" ixy="0.0" ixz="0.0" iyy="0.133885781862" iyz="0.0" izz="0.0151074"/>
    </inertial>
  </link>
  <joint name="elbow_joint" type="revolute">
    <parent link="upper_arm_link"/>
    <child link="forearm_link"/>
    <origin rpy="0.0 0.0 0.0" xyz="0.0 -0.131 0.425"/>
    <axis xyz="0 1 0"/>
    <limit effort="150.0" lower="-3.14159265359" upper="3.14159265359" velocity="3.14"/>
    <dynamics damping="0.0" friction="0.0"/>
  </joint>
  <link name="forearm_link">
    <visual>
      <geometry>
        <mesh filename="meshes/ur5e/visual/forearm.dae"/>
      </geometry>
      <origin rpy="1.57079632679 0 0" xyz="0.0 0.0 0.0"/>
      <!-- <material name="LightGrey">
        <color rgba="0.7 0.7 0.7 1.0"/>
      </material> -->
    </visual>
    <collision>
      <geometry>
        <mesh filename="meshes/ur5e/collision/forearm.stl" scale="1.0 1.0 1.0"/>
      </geometry>
    </collision>
    <inertial>
      <mass value="2.275"/>
      <origin rpy="0 0 0" xyz="0.0 0.0 0.196"/>
      <inertia ixx="0.0311796208615" ixy="0.0" ixz="0.0" iyy="0.0311796208615" iyz="0.0" izz="0.004095"/>
    </inertial>
  </link>
  <joint name="wrist_1_joint" type="revolute">
    <parent link="forearm_link"/>
    <child link="wrist_1_link"/>
    <origin rpy="0.0 1.57079632679 0.0" xyz="0.0 0.0 0.392"/>
    <axis xyz="0 1 0"/>
    <limit effort="28.0" lower="-6.28318530718" upper="6.28318530718" velocity="6.28"/>
    <dynamics damping="0.0" friction="0.0"/>
  </joint>
  <link name="wrist_1_link">
    <visual>
      <geometry>
        <mesh filename="meshes/ur5e/visual/wrist1.dae"/>
      </geometry>
      <origin rpy="1.57079632679 0 0" xyz="0.0 0.0 0.0"/>
      <!-- <material name="LightGrey">
        <color rgba="0.7 0.7 0.7 1.0"/>
      </material> -->
    </visual>
    <collision>
      <geometry>
        <mesh filename="meshes/ur5e/collision/wrist1.stl" scale="1.0 1.0 1.0"/>
      </geometry>
    </collision>
    <inertial>
      <mass value="1.219"/>
      <origin rpy="0 0 0" xyz="0.0 0.127 0.0"/>
      <inertia ixx="0.00255989897604" ixy="0.0" ixz="0.0" iyy="0.00255989897604" iyz="0.0" izz="0.0021942"/>
    </inertial>
  </link>
  <joint name="wrist_2_joint" type="revolute">
    <parent link="wrist_1_link"/>
    <child link="wrist_2_link"/>
    <origin rpy="0.0 0.0 0.0" xyz="0.0 0.127 0.0"/>
    <axis xyz="0 0 1"/>
    <limit effort="28.0" lower="-6.28318530718" upper="6.28318530718" velocity="6.28"/>
    <dynamics damping="0.0" friction="0.0"/>
  </joint>
  <link name="wrist_2_link">
    <visual>
      <geometry>
        <mesh filename="meshes/ur5e/visual/wrist2.dae"/>
      </geometry>
      <origin rpy="1.57079632679 0 0" xyz="0.0 0.0 0.0"/>
      <!-- <material name="LightGrey">
        <color rgba="0.7 0.7 0.7 1.0"/>
      </material> -->
    </visual>
    <collision>
      <geometry>
        <mesh filename="meshes/ur5e/collision/wrist2.stl" scale="1.0 1.0 1.0"/>
      </geometry>
    </collision>
    <inertial>
      <mass value="1.219"/>
      <origin rpy="0 0 0" xyz="0.0 0.0 0.1"/>
      <inertia ixx="0.00255989897604" ixy="0.0" ixz="0.0" iyy="0.00255989897604" iyz="0.0" izz="0.0021942"/>
    </inertial>
  </link>
  <joint name="wrist_3_joint" type="revolute">
    <parent link="wrist_2_link"/>
    <child link="wrist_3_link"/>
    <origin rpy="0.0 0.0 0.0" xyz="0.0 0.0 0.1"/>
    <axis xyz="0 1 0"/>
    <limit effort="28.0" lower="-6.28318530718" upper="6.28318530718" velocity="6.28"/>
    <dynamics damping="0.0" friction="0.0"/>
  </joint>
  <link name="wrist_3_link">
    <visual>
      <geometry>
        <mesh filename="meshes/ur5e/visual/wrist3.dae"/>
      </geometry>
      <origin rpy="1.57079632679 0 0" xyz="0.0 0.0 0.0"/>
      <!-- <material name="LightGrey">
        <color rgba="0.7 0.7 0.7 1.0"/>
      </material> -->
    </visual>
    <collision>
      <geometry>
        <mesh filename="meshes/ur5e/collision/wrist3.stl" scale="1.0 1.0 1.0"/>
      </geometry>
    </collision>
    <inertial>
      <mass value="0.1879"/>
      <origin rpy="1.57079632679 0 0" xyz="0.0 0.0771 0.0"/>
      <inertia ixx="9.89041005217e-05" ixy="0.0" ixz="0.0" iyy="9.89041005217e-05" iyz="0.0" izz="0.0001321171875"/>
    </inertial>
  </link>
  <joint name="ee_fixed_joint" type="fixed">
    <parent link="wrist_3_link"/>
    <child link="ee_link"/>
    <origin rpy="0.0 0.0 1.57079632679" xyz="0.0 0.1 0.0"/>
  </joint>
  <link name="ee_link">
    <collision>
      <geometry>
        <box size="0.01 0.01 0.01"/>
      </geometry>
      <origin rpy="0 0 0" xyz="-0.01 0 0"/>
    </collision>
  </link>

<link name="gripper_center">
</link>

  <joint name="gripper_center_joint" type="fixed">
    <parent link="ee_link"/>
    <child link="gripper_center"/>
    <origin rpy="0.00000 0.00000 0.00000" xyz="0.1525 0.0 0.0"/>
  </joint> 

  <!-- ====================Attach AllegroHand (right)==================== -->


  <!-- Hand Links -->
  <material name="grey">
    <color rgba="0.4 0.4 0.4 1"/>
  </material>
  <material name="black">
    <color rgba="0.1 0.1 0.1 1"/>
  </material>
  <joint name="hand_joint" type="fixed">
    	<parent link="ee_link"/>
    	<child link="hand_link"/>
    	<origin rpy="1.57 0 1.57" xyz="0.001 0 0"/>
    </joint>
  <link name="hand_link">
    <inertial>
      <origin rpy="0 0 0" xyz="-4.898915958379213e-05 2.84756960271082e-06 0.06811082379774974"/>
      <mass value="1.2646523179240972"/>
      <inertia ixx="0.001504" ixy="-0.0" ixz="-3e-06" iyy="0.001812" iyz="0.0" izz="0.001053"/>
    </inertial>
    <visual>
      <origin rpy="0 0 0" xyz="0 0 0"/>
      <geometry>
        <mesh filename="meshes/onrobot_2fg7_description/meshes/base_link.stl" scale="0.001 0.001 0.001"/>
      </geometry>
      <material name="grey"/>
    </visual>
    <collision>
      <origin rpy="0 0 0" xyz="0 0 0"/>
      <geometry>
        <mesh filename="meshes/onrobot_2fg7_description/meshes/base_link.stl" scale="0.001 0.001 0.001"/>
      </geometry>
    </collision>
  </link>
  <link name="right_finger_link">
    <inertial>
      <origin rpy="0 0 0" xyz="0.017874296677847158 0.02949104051991925 0.01523421548622829"/>
      <mass value="0.023219383355922288"/>
      <inertia ixx="6e-06" ixy="-0.0" ixz="1e-06" iyy="5e-06" iyz="-0.0" izz="2e-06"/>
    </inertial>
    <visual>
      <origin rpy="0 0 0" xyz="0.054361 0.029494 -0.12005"/>
      <geometry>
        <mesh filename="meshes/onrobot_2fg7_description/meshes/right_finger_link.stl" scale="0.001 0.001 0.001"/>
      </geometry>
      <material name="black"/>
    </visual>
    <collision name="right_finger_collision">
      <origin rpy="0 0 0" xyz="0.054361 0.029494 -0.12005"/>
      <geometry>
        <mesh filename="meshes/onrobot_2fg7_description/meshes/right_finger_link.stl" scale="0.001 0.001 0.001"/>
      </geometry>
    </collision>
  </link>
  <link name="left_finger_link">
    <inertial>
      <origin rpy="0 0 0" xyz="0.004247703322119739 0.029496959480080673 0.015234215486237948"/>
      <mass value="0.023219383355922288"/>
      <inertia ixx="6e-06" ixy="-0.0" ixz="-1e-06" iyy="5e-06" iyz="0.0" izz="2e-06"/>
    </inertial>
    <visual>
      <origin rpy="0 0 0" xyz="-0.032239 0.029494 -0.12005"/>
      <geometry>
        <mesh filename="meshes/onrobot_2fg7_description/meshes/left_finger_link.stl" scale="0.001 0.001 0.001"/>
      </geometry>
      <material name="black"/>
    </visual>
    <collision name="left_finger_collision">
      <origin rpy="0 0 0" xyz="-0.032239 0.029494 -0.12005"/>
      <geometry>
        <mesh filename="meshes/onrobot_2fg7_description/meshes/left_finger_link.stl" scale="0.001 0.001 0.001"/>
      </geometry>
    </collision>
  </link>

  <joint name="left_finger_joint" type="prismatic">
    <origin rpy="0 0 0" xyz="0.032239 -0.029494 0.12005"/>
    <parent link="hand_link"/>
    <child link="left_finger_link"/>
    <axis xyz="-1.0 0.0 0.0"/>
    <limit effort="140" lower="0" upper="0.019" velocity="0.45"/>
    <dynamics damping="0.001" friction="0.001" />
    <implicitSpringDamper>True</implicitSpringDamper>
    <!-- total 0.38 -->
  </joint>

  <joint name="right_finger_joint" type="prismatic">
    <origin rpy="0 0 0" xyz="-0.054361 -0.029494 0.12005"/>
    <parent link="hand_link"/>
    <child link="right_finger_link"/>
    <axis xyz="1.0 0.0 0.0"/>
    <limit effort="140" lower="0" upper="0.019" velocity="0.45"/>
    <!-- <mimic joint="left_finger_joint" multiplier="1.0"/> -->
    <dynamics damping="0.001" friction="0.001" />
    <implicitSpringDamper>True</implicitSpringDamper>
  </joint>

  <joint name="ur10_leftfinger_ft_sensor_joint" type="fixed">
        <parent link="left_finger_link"/>
        <child link="ur10_leftfinger_ft_sensor"/>
        <origin rpy="0 -1.57 0" xyz="0.003247703322119739 0.029496959480080673 0.027234215486237948"/>
        <!-- <origin rpy="0 0 0" xyz="0.004247703322119739 0.029496959480080673 0.015234215486237948"/> -->
    </joint>
    <link name="ur10_leftfinger_ft_sensor">
        <visual>
            <origin rpy="0 0 0" xyz="0 0 0"/>
            <geometry>
                <cylinder radius="0.008" length="0.001"/>
            </geometry>
            <material name="red">
                <color rgba="1.0 0.0 0.0 1.0"/>
            </material>
        </visual>
        <collision>
            <origin rpy="0 0 0" xyz="0 0 0"/>
            <geometry>
                <cylinder radius="0.008" length="0.001"/>
            </geometry>
        </collision>
    </link>
    <joint name="ur10_rightfinger_ft_sensor_joint" type="fixed">
        <parent link="right_finger_link"/>
        <child link="ur10_rightfinger_ft_sensor"/>
        <origin rpy="0 -1.57 0" xyz="0.018874296677847158 0.02949104051991925 0.02723421548622829"/>
        <!-- <origin rpy="0 -1.57 0" xyz="0.017874296677847158 0.02949104051991925 0.01523421548622829"/> -->
    </joint>
    <link name="ur10_rightfinger_ft_sensor">
        <visual>
            <origin rpy="0 0 1.57" xyz="0 0 0"/>
            <geometry>
                <cylinder radius="0.008" length="0.001"/>
            </geometry>
            <material name="red">
                <color rgba="1.0 0.0 0.0 1.0"/>
            </material>
        </visual>
        <collision>
            <origin rpy="0 0 1.57" xyz="0 0 0"/>
            <geometry>
                <cylinder radius="0.008" length="0.001"/>
            </geometry>
        </collision>
    </link>

</robot>
