<?xml version="1.0" encoding="utf-8"?>
<robot name="ur5e">
  <material name="white">
    <color rgba="1 1 1 1"/>
  </material>
  <material name="silver">
    <color rgba="0.700 0.700 0.700 1.000"/>
  </material>
  <material name="blue">
    <color rgba="0.21568627450980393 0.592156862745098 0.8117647058823529 1.000"/>
  </material>
  <link name="base_link">
    <visual>
      <geometry>
        <mesh filename="meshes/ur5e/visual/base.dae"/>
      </geometry>
      <origin rpy="1.57079632679 0 0" xyz="0.0 0.0 0.0"/>
      <!-- <material name="LightGrey">
        <color rgba="0.7 0.7 0.7 1.0"/>
      </material> -->
    </visual>
    <collision>
      <geometry>
        <mesh filename="meshes/ur5e/collision/base.stl" scale="1.0 1.0 1.0"/>
      </geometry>
    </collision>
    <inertial>
      <mass value="4.0"/>
      <origin rpy="0 0 0" xyz="0.0 0.0 0.0"/>
      <inertia ixx="0.00443333156" ixy="0.0" ixz="0.0" iyy="0.00443333156" iyz="0.0" izz="0.0072"/>
    </inertial>
  </link>
  <joint name="shoulder_pan_joint" type="revolute">
    <parent link="base_link"/>
    <child link="shoulder_link"/>
    <origin rpy="0.0 0.0 0.0" xyz="0.0 0.0 0.163"/>
    <axis xyz="0 0 1"/>
    <limit effort="150.0" lower="-6.28318530718" upper="6.28318530718" velocity="3.14"/>
    <dynamics damping="0.0" friction="0.0"/>
  </joint>
  <link name="shoulder_link">
    <visual>
      <geometry>
        <mesh filename="meshes/ur5e/visual/shoulder.dae"/>
      </geometry>
      <origin rpy="1.57079632679 0 0" xyz="0.0 0.0 0.0"/>
      <!-- <material name="LightGrey">
        <color rgba="0.7 0.7 0.7 1.0"/>
      </material> -->
    </visual>
    <collision>
      <geometry>
        <mesh filename="meshes/ur5e/collision/shoulder.stl" scale="1.0 1.0 1.0"/>
      </geometry>
    </collision>
    <inertial>
      <mass value="3.7"/>
      <origin rpy="0 0 0" xyz="0.0 0.0 0.0"/>
      <inertia ixx="0.010267495893" ixy="0.0" ixz="0.0" iyy="0.010267495893" iyz="0.0" izz="0.00666"/>
    </inertial>
  </link>
  <joint name="shoulder_lift_joint" type="revolute">
    <parent link="shoulder_link"/>
    <child link="upper_arm_link"/>
    <origin rpy="0.0 1.57079632679 0.0" xyz="0.0 0.138 0.0"/>
    <axis xyz="0 1 0"/>
    <limit effort="150.0" lower="-6.28318530718" upper="6.28318530718" velocity="3.14"/>
    <dynamics damping="0.0" friction="0.0"/>
  </joint>
  <link name="upper_arm_link">
    <visual>
      <geometry>
        <mesh filename="meshes/ur5e/visual/upperarm.dae"/>
      </geometry>
      <origin rpy="1.57079632679 0 0" xyz="0.0 0.0 0.0"/>
      <!-- <material name="LightGrey">
        <color rgba="0.7 0.7 0.7 1.0"/>
      </material> -->
    </visual>
    <collision>
      <geometry>
        <mesh filename="meshes/ur5e/collision/upperarm.stl" scale="1.0 1.0 1.0"/>
      </geometry>
    </collision>
    <inertial>
      <mass value="8.393"/>
      <origin rpy="0 0 0" xyz="0.0 0.0 0.2125"/>
      <inertia ixx="0.133885781862" ixy="0.0" ixz="0.0" iyy="0.133885781862" iyz="0.0" izz="0.0151074"/>
    </inertial>
  </link>
  <joint name="elbow_joint" type="revolute">
    <parent link="upper_arm_link"/>
    <child link="forearm_link"/>
    <origin rpy="0.0 0.0 0.0" xyz="0.0 -0.131 0.425"/>
    <axis xyz="0 1 0"/>
    <limit effort="150.0" lower="-3.14159265359" upper="3.14159265359" velocity="3.14"/>
    <dynamics damping="0.0" friction="0.0"/>
  </joint>
  <link name="forearm_link">
    <visual>
      <geometry>
        <mesh filename="meshes/ur5e/visual/forearm.dae"/>
      </geometry>
      <origin rpy="1.57079632679 0 0" xyz="0.0 0.0 0.0"/>
      <!-- <material name="LightGrey">
        <color rgba="0.7 0.7 0.7 1.0"/>
      </material> -->
    </visual>
    <collision>
      <geometry>
        <mesh filename="meshes/ur5e/collision/forearm.stl" scale="1.0 1.0 1.0"/>
      </geometry>
    </collision>
    <inertial>
      <mass value="2.275"/>
      <origin rpy="0 0 0" xyz="0.0 0.0 0.196"/>
      <inertia ixx="0.0311796208615" ixy="0.0" ixz="0.0" iyy="0.0311796208615" iyz="0.0" izz="0.004095"/>
    </inertial>
  </link>
  <joint name="wrist_1_joint" type="revolute">
    <parent link="forearm_link"/>
    <child link="wrist_1_link"/>
    <origin rpy="0.0 1.57079632679 0.0" xyz="0.0 0.0 0.392"/>
    <axis xyz="0 1 0"/>
    <limit effort="28.0" lower="-6.28318530718" upper="6.28318530718" velocity="6.28"/>
    <dynamics damping="0.0" friction="0.0"/>
  </joint>
  <link name="wrist_1_link">
    <visual>
      <geometry>
        <mesh filename="meshes/ur5e/visual/wrist1.dae"/>
      </geometry>
      <origin rpy="1.57079632679 0 0" xyz="0.0 0.0 0.0"/>
      <!-- <material name="LightGrey">
        <color rgba="0.7 0.7 0.7 1.0"/>
      </material> -->
    </visual>
    <collision>
      <geometry>
        <mesh filename="meshes/ur5e/collision/wrist1.stl" scale="1.0 1.0 1.0"/>
      </geometry>
    </collision>
    <inertial>
      <mass value="1.219"/>
      <origin rpy="0 0 0" xyz="0.0 0.127 0.0"/>
      <inertia ixx="0.00255989897604" ixy="0.0" ixz="0.0" iyy="0.00255989897604" iyz="0.0" izz="0.0021942"/>
    </inertial>
  </link>
  <joint name="wrist_2_joint" type="revolute">
    <parent link="wrist_1_link"/>
    <child link="wrist_2_link"/>
    <origin rpy="0.0 0.0 0.0" xyz="0.0 0.127 0.0"/>
    <axis xyz="0 0 1"/>
    <limit effort="28.0" lower="-6.28318530718" upper="6.28318530718" velocity="6.28"/>
    <dynamics damping="0.0" friction="0.0"/>
  </joint>
  <link name="wrist_2_link">
    <visual>
      <geometry>
        <mesh filename="meshes/ur5e/visual/wrist2.dae"/>
      </geometry>
      <origin rpy="1.57079632679 0 0" xyz="0.0 0.0 0.0"/>
      <!-- <material name="LightGrey">
        <color rgba="0.7 0.7 0.7 1.0"/>
      </material> -->
    </visual>
    <collision>
      <geometry>
        <mesh filename="meshes/ur5e/collision/wrist2.stl" scale="1.0 1.0 1.0"/>
      </geometry>
    </collision>
    <inertial>
      <mass value="1.219"/>
      <origin rpy="0 0 0" xyz="0.0 0.0 0.1"/>
      <inertia ixx="0.00255989897604" ixy="0.0" ixz="0.0" iyy="0.00255989897604" iyz="0.0" izz="0.0021942"/>
    </inertial>
  </link>
  <joint name="wrist_3_joint" type="revolute">
    <parent link="wrist_2_link"/>
    <child link="wrist_3_link"/>
    <origin rpy="0.0 0.0 0.0" xyz="0.0 0.0 0.1"/>
    <axis xyz="0 1 0"/>
    <limit effort="28.0" lower="-6.28318530718" upper="6.28318530718" velocity="6.28"/>
    <dynamics damping="0.0" friction="0.0"/>
  </joint>
  <link name="wrist_3_link">
    <visual>
      <geometry>
        <mesh filename="meshes/ur5e/visual/wrist3.dae"/>
      </geometry>
      <origin rpy="1.57079632679 0 0" xyz="0.0 0.0 0.0"/>
      <!-- <material name="LightGrey">
        <color rgba="0.7 0.7 0.7 1.0"/>
      </material> -->
    </visual>
    <collision>
      <geometry>
        <mesh filename="meshes/ur5e/collision/wrist3.stl" scale="1.0 1.0 1.0"/>
      </geometry>
    </collision>
    <inertial>
      <mass value="0.1879"/>
      <origin rpy="1.57079632679 0 0" xyz="0.0 0.0771 0.0"/>
      <inertia ixx="9.89041005217e-05" ixy="0.0" ixz="0.0" iyy="9.89041005217e-05" iyz="0.0" izz="0.0001321171875"/>
    </inertial>
  </link>
  <joint name="ee_fixed_joint" type="fixed">
    <parent link="wrist_3_link"/>
    <child link="ee_link"/>
    <origin rpy="0.0 0.0 1.57079632679" xyz="0.0 0.1 0.0"/>
  </joint>
  <link name="ee_link">
    <collision>
      <geometry>
        <box size="0.01 0.01 0.01"/>
      </geometry>
      <origin rpy="0 0 0" xyz="-0.01 0 0"/>
    </collision>
  </link>

  <!-- ====================Attach AllegroHand (right)==================== -->

  <link name="quick_changer">
    <inertial>
      <origin rpy="0 0 0" xyz="0.0014673787228634701 -0.0007395056519161622 0.00391087859435364"/>
      <mass value="0.05802030412577654"/>
      <inertia ixx="2e-05" ixy="-0.0" ixz="-0.0" iyy="2.7e-05" iyz="0.0" izz="4.5e-05"/>
    </inertial>
    <visual>
      <origin rpy="0 0 0" xyz="0 0 0"/>
      <geometry>
        <mesh filename="visual/quick_changer.stl" scale="0.001 0.001 0.001"/>
      </geometry>
      <!-- <material name="blue"/> -->
    </visual>
    <collision>
      <origin rpy="0 0 0" xyz="0 0 0"/>
      <geometry>
        <mesh filename="collision/quick_changer.stl" scale="0.001 0.001 0.001"/>
      </geometry>
    </collision>
  </link>
  <link name="gripper_body">
    <inertial>
      <origin rpy="0 0 0" xyz="0.0272971231150397 -0.002438088956580745 0.035297715994502724"/>
      <mass value="0.5707794664902835"/>
      <inertia ixx="0.000622" ixy="3e-06" ixz="0.0" iyy="0.000662" iyz="1.8e-05" izz="0.000226"/>
    </inertial>
    <visual>
      <origin rpy="0 0 0" xyz="0.02705 -0.0 -0.047"/>
      <geometry>
        <mesh filename="visual/gripper_body.stl" scale="0.001 0.001 0.001"/>
      </geometry>
      <material name="silver"/>
    </visual>
    <collision>
      <origin rpy="0 0 0" xyz="0.02705 -0.0 -0.047"/>
      <geometry>
        <mesh filename="collision/gripper_body.stl" scale="0.001 0.001 0.001"/>
      </geometry>
    </collision>
  </link>
  <link name="angle_bracket">
    <inertial>
      <origin rpy="0 0 0" xyz="-0.00023577776357350244 0.0006406606087327927 0.01993861451986476"/>
      <mass value="0.19757034519537245"/>
      <inertia ixx="9.8e-05" ixy="-0.0" ixz="-1e-06" iyy="0.000145" iyz="2e-06" izz="0.000155"/>
    </inertial>
    <visual>
      <origin rpy="0 0 0" xyz="-0.0 -0.0 -0.00255"/>
      <geometry>
        <mesh filename="visual/angle_bracket.stl" scale="0.001 0.001 0.001"/>
      </geometry>
      <material name="silver"/>
    </visual>
    <collision>
      <origin rpy="0 0 0" xyz="-0.0 -0.0 -0.00255"/>
      <geometry>
        <mesh filename="collision/angle_bracket.stl" scale="0.001 0.001 0.001"/>
      </geometry>
    </collision>
  </link>
  <link name="left_inner_knuckle">
    <inertial>
      <origin rpy="0 0 0" xyz="0.01762916513992015 0.010471874847992522 0.017068183318320468"/>
      <mass value="0.024337519273275633"/>
      <inertia ixx="5e-06" ixy="-0.0" ixz="-3e-06" iyy="7e-06" iyz="-0.0" izz="5e-06"/>
    </inertial>
    <visual>
      <origin rpy="0 0 0" xyz="-0.0075 0.009367 -0.139397"/>
      <geometry>
        <mesh filename="visual/left_inner_knuckle.stl" scale="0.001 0.001 0.001"/>
      </geometry>
      <material name="silver"/>
    </visual>
    <collision>
      <origin rpy="0 0 0" xyz="-0.0075 0.009367 -0.139397"/>
      <geometry>
        <mesh filename="collision/left_inner_knuckle.stl" scale="0.001 0.001 0.001"/>
      </geometry>
    </collision>
  </link>
  <link name="right_outer_knuckle">
    <inertial>
      <origin rpy="0 0 0" xyz="-0.012312223780380358 0.010369678145266329 0.010203759185649544"/>
      <mass value="0.041583686281793396"/>
      <inertia ixx="1e-05" ixy="0.0" ixz="7e-06" iyy="1.6e-05" iyz="-0.0" izz="1e-05"/>
    </inertial>
    <visual>
      <origin rpy="0 0 0" xyz="0.017 0.009534 -0.122898"/>
      <geometry>
        <mesh filename="visual/right_outer_knuckle.stl" scale="0.001 0.001 0.001"/>
      </geometry>
      <material name="silver"/>
    </visual>
    <collision>
      <origin rpy="0 0 0" xyz="0.017 0.009534 -0.122898"/>
      <geometry>
        <mesh filename="collision/right_outer_knuckle.stl" scale="0.001 0.001 0.001"/>
      </geometry>
    </collision>
  </link>
  <link name="left_outer_knuckle">
    <inertial>
      <origin rpy="0 0 0" xyz="0.01231204747983699 0.010369678145260136 0.01020375918419171"/>
      <mass value="0.04158368628179342"/>
      <inertia ixx="1e-05" ixy="-0.0" ixz="-7e-06" iyy="1.6e-05" iyz="-0.0" izz="1e-05"/>
    </inertial>
    <visual>
      <origin rpy="0 0 0" xyz="-0.017 0.009534 -0.122898"/>
      <geometry>
        <mesh filename="visual/left_outer_knuckle.stl" scale="0.001 0.001 0.001"/>
      </geometry>
      <material name="silver"/>
    </visual>
    <collision>
      <origin rpy="0 0 0" xyz="-0.017 0.009534 -0.122898"/>
      <geometry>
        <mesh filename="collision/left_outer_knuckle.stl" scale="0.001 0.001 0.001"/>
      </geometry>
    </collision>
  </link>
  <link name="left_inner_finger">
    <inertial>
      <origin rpy="0 0 0" xyz="-0.009341477027312806 0.006108535220686467 0.03133683897712786"/>
      <mass value="0.03203868115594587"/>
      <inertia ixx="9e-06" ixy="0.0" ixz="2e-06" iyy="9e-06" iyz="-0.0" izz="2e-06"/>
    </inertial>
    <visual>
      <origin rpy="0 0 0" xyz="-0.056748 0.00475 -0.160866"/>
      <geometry>
        <mesh filename="visual/left_inner_finger.stl" scale="0.001 0.001 0.001"/>
      </geometry>
      <material name="silver"/>
    </visual>
    <collision>
      <origin rpy="0 0 0" xyz="-0.056748 0.00475 -0.160866"/>
      <geometry>
        <mesh filename="collision/left_inner_finger.stl" scale="0.001 0.001 0.001"/>
      </geometry>
    </collision>
  </link>
  <link name="right_inner_finger">
    <inertial>
      <origin rpy="0 0 0" xyz="0.009341300963273541 0.006108535097342211 0.03133683984830843"/>
      <mass value="0.032038680057528524"/>
      <inertia ixx="9e-06" ixy="-0.0" ixz="-2e-06" iyy="9e-06" iyz="-0.0" izz="2e-06"/>
    </inertial>
    <visual>
      <origin rpy="0 0 0" xyz="0.056748 0.00475 -0.160866"/>
      <geometry>
        <mesh filename="visual/right_inner_finger.stl" scale="0.001 0.001 0.001"/>
      </geometry>
      <material name="silver"/>
    </visual>
    <collision>
      <origin rpy="0 0 0" xyz="0.056748 0.00475 -0.160866"/>
      <geometry>
        <mesh filename="collision/right_inner_finger.stl" scale="0.001 0.001 0.001"/>
      </geometry>
    </collision>
  </link>
  <link name="right_inner_knuckle">
    <inertial>
      <origin rpy="0 0 0" xyz="-0.017629341439301484 0.010471874848001397 0.017068183319570135"/>
      <mass value="0.024337519273275623"/>
      <inertia ixx="5e-06" ixy="0.0" ixz="3e-06" iyy="7e-06" iyz="-0.0" izz="5e-06"/>
    </inertial>
    <visual>
      <origin rpy="0 0 0" xyz="0.0075 0.009367 -0.139397"/>
      <geometry>
        <mesh filename="visual/right_inner_knuckle.stl" scale="0.001 0.001 0.001"/>
      </geometry>
      <material name="silver"/>
    </visual>
    <collision>
      <origin rpy="0 0 0" xyz="0.0075 0.009367 -0.139397"/>
      <geometry>
        <mesh filename="collision/right_inner_knuckle.stl" scale="0.001 0.001 0.001"/>
      </geometry>
    </collision>
  </link>
  <joint name="quick_changer_joint" type="fixed">
    <parent link="ee_link"/>
    <child link="quick_changer"/>
    <origin rpy="1.57079632679 1.57079632679 1.57079632679" xyz="0 0 0"/>
  </joint>
  <joint name="gripper_body_joint" type="fixed">
    <origin rpy="0.010122909661567111 0 0" xyz="-0.02705 0.0 0.04445"/>
    <parent link="angle_bracket"/>
    <child link="gripper_body"/>
  </joint>
  <joint name="angle_bracket_joint" type="fixed">
    <origin rpy="0 0 0" xyz="0.0 0.0 0.00255"/>
    <parent link="quick_changer"/>
    <child link="angle_bracket"/>
  </joint>
  <joint name="left_inner_knuckle_joint" type="revolute">
    <origin rpy="0 0.4153883619746504 0" xyz="0.03455 -0.009367 0.092397"/>
    <parent link="gripper_body"/>
    <child link="left_inner_knuckle"/>
    <axis xyz="-0.0 0.999949 -0.010122"/>
    <limit effort="50.0" lower="-1.19" upper="0.01" velocity="2.0"/>
    <mimic joint="finger_joint" multiplier="-1" offset="0"/>
  </joint>
  <joint name="finger_joint" type="revolute">
    <origin rpy="0 -0.4153883619746504 0" xyz="0.01005 -0.009534 0.075898"/>
    <parent link="gripper_body"/>
    <child link="right_outer_knuckle"/>
    <axis xyz="-0.0 0.999949 -0.010122"/>
    <limit effort="50.0" lower="0" upper="1.18" velocity="2.0"/>
  </joint>
  <joint name="left_outer_knuckle_joint" type="revolute">
    <origin rpy="0 0.4153883619746504 0" xyz="0.04405 -0.009534 0.075898"/>
    <parent link="gripper_body"/>
    <child link="left_outer_knuckle"/>
    <axis xyz="-0.0 0.999949 -0.010122"/>
    <limit effort="50.0" lower="-1.19" upper="0.01" velocity="2.0"/>
  
  </joint>
  <joint name="left_inner_finger_joint" type="revolute">
    <origin rpy="0 -0.4153883619746504 0" xyz="0.039748 0.004784 0.037968"/>
    <parent link="left_outer_knuckle"/>
    <child link="left_inner_finger"/>
    <axis xyz="0.0 -0.999949 0.010122"/>
    <limit effort="50.0" lower="-1.19" upper="0.01" velocity="2.0"/>
  </joint>
  <joint name="right_inner_finger_joint" type="revolute">
    <origin rpy="0 0.4153883619746504 0" xyz="-0.039748 0.004784 0.037968"/>
    <parent link="right_outer_knuckle"/>
    <child link="right_inner_finger"/>
    <axis xyz="0.0 0.999949 -0.010122"/>
    <limit effort="50.0" lower="-1.19" upper="0.01" velocity="2.0"/>
  </joint>
  <joint name="right_inner_knuckle_joint" type="revolute">
    <origin rpy="0 -0.4153883619746504 0" xyz="0.01955 -0.009367 0.092397"/>
    <parent link="gripper_body"/>
    <child link="right_inner_knuckle"/>
    <axis xyz="-0.0 0.999949 -0.010122"/>
    <limit effort="50.0" lower="-0.01" upper="1.19" velocity="2.0"/>
  </joint>
  <!-- End-effector -->
  <link name="tool0"/>
  <joint name="end_effector_frame_fixed_joint" type="fixed">
    <parent link="wrist_3_link"/>
    <child link="tool0"/>
    <origin xyz="0 0.275 0" rpy="-1.570796325 0 0"/>
  </joint>
</robot>
